//doing same thing using two different way first using promises and second using try/catch
const asyncHandler = (requestHandler) => {
  (req, res, next) => {
    Promise.resolve(requestHandler(req, res, next)).catch((err) => next(err));
  };
};

// const asyncHandler = (fn) => async (req, res, next) => {
//   try {
//     await fn(req, res, next);
//   } catch (error) {
//     res.status(error.code || 500).json({
//       success: false,
//       message: error.message,
//     });
//   }
// };
export { asyncHandler };
